Workbook
Name 电池簇级: Sheet1!$B$2:$B$6546
Name 电池组级: Sheet1!$A$2:$A$6546
Name 类型: OFFSET([1]配置!$A$1,,,,COUNTA([1]配置!$1:$1))
Name 类型: OFFSET([2]配置!$A$1,,,,COUNTA([2]配置!$1:$1))
Name 系统级: Sheet1!$C$2:$C$6546

Sheet 第三方接口信息
B2: 第三方接口信息
A4: # | B4: 接口名称 | C4: 转发内容描述 | D4: 源系统名称 | E4: 源系统厂家 | F4: 接口所在屏柜位置 | G4: 规约类型 | H4: 典型应用场景
A5: 1 | B5: 储能设备接口 | C5: 储能设备数据 | D5: 站端监控系统 | E5: 新源智储 | F5: 储能系统数据网屏柜 | G5: IEC104 | I5: 样例
A6: 2

Sheet 0-场站电气拓扑图
B2: 场站电气拓扑图

Sheet 1-场站
A1: #填写说明# 1. 此模版为储能场站基础信息表，此页为必填页 2. 标注“*”的为重要填写项 3. 已标明单位的填写项直接按单位写入相应参数值，填写时不能带有单位 4.蓝色标题为仅EnOS需要收资，绿色标题为仅Scada需要收资
A2: 填写指导： | B2: 按UTC标准时区格式进行配置：UTC+/-XX:YY，+、-代表正负时区，仅支持配置整时区。 填写示例：UTC+08:00 | C2: 仅Scada需要填写 场站监控所使用的语言 | D2: 场站详细地址 | E2: 对外宣称容量，单位是MWh | F2: 对外宣称额定充放电功率，单位是MW | G2: 东经为正，西经为负。 以多位小数表示，单位为°。 填写车站实际位置的纬度，精确到小数点后六位。 建议使用google/baidu地图查询坐标 示例：121.473523 | H2: 北纬为正，南纬为负，以多位小数表示，单位为°。填写车站实际位置的纬度，精确到小数点后六位。建议使用google/ 百度地图查询坐标 示例：31.230427 | I2: 仅EnOS需填写： 储能系统数量需要等于此场站下的储能系统数量之和 | J2: 仅EnOS需填写： 可选择1.1 物理场站页面中配置的物理场站，导入后会在系统中自动生成物理场站，如多个场站属于同一个物理场站请务必保证物理场站的名称一致。 | K2: 仅EnOS需填写： 选择配套储能、风储、光储、独立储能、户用储能等 | L2: 仅EnOS需填写： 站端scada的scada别名 | M2: 仅EnOS需填写： 储能进线-升压站出线的升压站等级 | N2: 仅EnOS需填写： 储能场站所关联升压站的出线名称
A3: 名称* | B3: 时区* | C3: 语言* | D3: 场站详细地址* | E3: 场站额定容量* | F3: 场站额定功率* | G3: 经度* | H3: 纬度* | I3: 储能系统数量* | J3: 所属物理场站* | K3: 场站类型* | L3: Scada别名 | M3: 升压等级 | N3: 电网线路名称

Sheet 1.1 物理场站
A1: #填写说明#（仅EnOS需填写） 1. 物理场站下挂载风+升压站、光+升压站、储能+升压站，或者风光储场站+升压站，用于管理连接同一升压站的多个不同场站。 2.若该物理场站名称不存在，系统会在导入时，创建该物理场站；如该物理场站名称已存在，则系统会默认为同一物理场站，所以共用一个升压站的风场、光伏场站、升压站场站的物理场站名称一定要填写一致
A2: 填写指导：
A3: 名称*

Sheet 2-储能系统
A1: #填写说明# 1. 此模版为储能系统基础信息表，此页为必填页 2. 标注“*”的为重要填写项 3. 已标明单位的填写项直接按单位写入相应参数值，填写时不能带有单位 4.蓝色标题为仅EnOS需要收资，绿色标题为仅Scada需要收资
A2: 填写指导： | B2: 如有多种厂家，需分别填写 | C2: 如有多种规格，需分别填写 | D2: 已安装电池的总能量容量(kWh) | E2: 已安装 PCS 的总功率容量(kW) | F2: 储能系统所属的升压站进线 | G2: 仅EnOS需填写： 选择集中式、组串式、分散式 集中式：一个PCS对应一个电池组和多个电池簇； 组串式：一组PCS对应一个电池组和多个电池簇； 分散式：多个PCS对应多个电池簇，PCS与电池簇一一连接，无电池组 | H2: 仅EnOS需填写： 设备的编号，要求不超过3位，如：“01” | I2: 仅EnOS需填写： 站端scada的scada别名 | J2: 远景填写，公式自动拼接 | K2: 仅EnOS需填写：（远景填写） 如果创建设备需要指定模型，请填写指定的模型ID，否则无需填写
A3: 名称* | B3: 制造厂家* | C3: 型号* | D3: 额定容量* | E3: 额定功率* | F3: 所属升压站进线名称* | G3: PCS连接形式* | H3: 序号* | I3: Scada别名 | J3: 已接入系统构成* | K3: 模型ID

Sheet 3-箱变
A1: #填写说明# 1. 此模版为储能箱变基础信息表，此页为必填页 2. 标注“*”的为重要填写项 3. 已标明单位的填写项直接按单位写入相应参数值，填写时不能带有单位 4.蓝色标题为仅EnOS需要收资，绿色标题为仅Scada需要收资
A2: 填写指导： | B2: 如有多种厂家，需分别填写 | C2: 如有多种规格，需分别填写 | D2: 仅Scada需要填写 选择对应的箱变类型 | E2: 箱变所属的储能系统 | G2: 仅EnOS需填写： 枚举量，选择风冷或油冷 | H2: 仅EnOS需填写： 箱变在场站下的编号，要求不超过3位，如：“01”，表示场站内的1号箱变 | I2: 仅EnOS需填写： 站端scada的scada别名 | J2: 仅EnOS需填写：（远景填写） 如果创建设备需要指定模型，请填写指定的模型ID，否则无需填写
A3: 名称* | B3: 制造厂家* | C3: 型号* | D3: 箱变类型* | E3: 所属系统* | F3: EnOS箱变类型* | G3: 冷却系统类型* | H3: 序号* | I3: Scada别名 | J3: 模型ID

Sheet 4-变流器
A1: #填写说明# 1. 此模版为储能变流器基础信息表，此页为必填页 2. 标注“*”的为重要填写项 3. 已标明单位的填写项直接按单位写入相应参数值，填写时不能带有单位
A2: 填写指导： | B2: 如有多种厂家，需分别填写 | C2: 如有多种规格，需分别填写 | D2: 变流器所属的箱变 | E2: 若PCS为组串式和分散式则需要填写，组串式PCS一般是一拖N的结构，例如一个系统5组PCS整机，每个整机拖4个PCS分机，则组编号即为1-5组 | F2: 仅EnOS需填写： 额定功率(kW) | G2: 仅EnOS需填写： 选择“交流/直流”或“直流/直流”，按实际情况填写，大部分选“交流/直流” | H2: 变流器所属的储能系统 | I2: 仅EnOS需填写： 变流器在系统内的编号，要求不超过3位，如：“01”，不同系统下的变流器编号会相同，如1#系统和2#下都会有01#变流器 | J2: 仅EnOS需填写： 站端scada的scada别名 | K2: 仅EnOS需填写：（远景填写） 如果创建设备需要指定模型，请填写指定的模型ID，否则无需填写
A3: 名称* | B3: 制造厂家* | C3: 设备型号* | D3: 所属箱变* | E3: PCS组编号 | F3: 额定功率* | G3: PCS类型* | H3: 所属系统* | I3: 序号* | J3: Scada别名 | K3: 模型ID

Sheet 5-舱
A1: #填写说明#(仅Scada需填写) 1. 此模版为储能系统基础信息表，此页为必填页 2. 标注“*”的为重要填写项 3. 已标明单位的填写项直接按单位写入相应参数值，填写时不能带有单位 4. BMS下无法识别具体设备的测点均归属于直流舱
A2: 填写指导： | B2: 如有多种厂家，需分别填写 | C2: 如有多种规格，需分别填写 | D2: 所属的储能系统 | E2: 仅EnOS需填写： 站端scada的scada别名
A3: 名称* | B3: 制造厂家 | C3: 型号 | D3: 所属系统* | E3: Scada别名

Sheet 6-电池组
A1: #填写说明# 1. 此模版为储能电池组基础信息表，若场站没有电池组则此页可不填 2. 标注“*”的为重要填写项 3. 已标明单位的填写项直接按单位写入相应参数值，填写时不能带有单位
A2: 填写指导： | B2: 如有多种厂家，需分别填写 | C2: 如有多种规格，需分别填写 | D2: 电池组所关联的变流器 | E2: 已安装电池的总能量容量(kWh) | F2: 仅EnOS需填写： 站端scada的scada别名 | G2: 仅EnOS需填写：（远景填写） 如果创建设备需要指定模型，请填写指定的模型ID，否则无需填写
A3: 名称* | B3: 制造厂家* | C3: 型号* | D3: 所属变流器* | E3: 额定容量* | F3: Scada别名 | G3: 模型ID

Sheet 7-电池簇
A1: #填写说明# 1. 此模版为储能电池簇基础信息表，此页为必填页 2. 标注“*”的为重要填写项 3. 已标明单位的填写项直接按单位写入相应参数值，填写时不能带有单位 4.蓝色标题为仅EnOS需要收资，绿色标题为仅Scada需要收资
A2: 填写指导： | B2: 如有多种厂家，需分别填写 | C2: 如有多种规格，需分别填写 | D2: 额定容量(kWh) | E2: 仅Scada需要填写 充电额定功率(kW) | F2: 仅Scada需要填写 放电额定功率(kW) | G2: 仅Scada需要填写 充电额定电压(V) | H2: 仅Scada需要填写 放电额定电压(V) | I2: 仅Scada需要填写 电池类型 | J2: 仅Scada需要填写 如果不是远景供应的电池，则填No | K2: 根据电池簇的实际连接关系填写其中的一列或两列： 1、若电池簇直接挂在电池组下，则填写“所属电池组”； 2、若没有电池组，电池簇直接挂在PCS下，则填写“所属PCS”； 3、若没有电池组，电池簇与PCS为多对多关系，则对每组PCS进行编号后，需填写“所属PCS”与“所属舱”，所属PCS仅需填写此分组的第一个PCS。例：1#电池簇与1#PCS组关联，1#PCS组有5个PCS，则所属PCS仅需填写1#PCS | N2: 单个电池簇包含的电芯数量 | O2: 仅EnOS需填写： 电池簇在系统内的编号，要求不超过3位，如：“102”，102表示1#电池组下的02电池簇 | P2: 仅EnOS需填写： 站端scada的scada别名 | Q2: 仅EnOS需填写：（远景填写） 如果创建设备需要指定模型，请填写指定的模型ID，否则无需填写
A3: 名称* | B3: 制造厂家* | C3: 设备型号* | D3: 额定容量* | E3: 充电额定功率* | F3: 放电额定功率* | G3: 充电额定电压* | H3: 放电额定电压* | I3: 电池簇类型* | J3: 是否远景电池簇* | K3: 所属电池组 | L3: 所属PCS | M3: 所属舱 | N3: 包含电芯数量 | O3: 序号* | P3: Scada别名 | Q3: 模型ID

Sheet 8-空调
A1: #填写说明# 1. 此模版为储能空调基础信息表，此页为必填页 2. 标注“*”的为重要填写项 3. 已标明单位的填写项直接按单位写入相应参数值，填写时不能带有单位 4.若同时拥有液冷机组和空调两类设备，则添加多行记录即可。
A2: 填写指导： | B2: 如有多种厂家，需分别填写 | C2: 如有多种规格，需分别填写 | D2: 液冷或风冷（液冷对应“液冷机组”，风冷对应“空调”） | E2: 填写：系统级、电池组级、电池簇级，表示一个空调机组所覆盖的设备范围 | F2: 所属的储能系统 | G2: 仅EnOS需填写： 电池簇级别填写此空调覆盖的电池包数量,非电池簇级别空调填写NULL | H2: 仅EnOS需填写： 电池组级别填写此空调覆盖的电池簇数量,非电池组级别空调填写NULL | I2: 仅EnOS需填写： 空调设备所属的上级节点 | J2: 仅EnOS需填写： 空调在系统内的编号，要求不超过3位，如：电池簇级空调的“102”，102表示102号电池簇关联的空调；电池组级的空调“02”表示此电池组级别空调的02号。 | K2: 仅EnOS需填写： 站端scada的scada别名 | L2: 仅EnOS需填写：（远景填写） 如果创建设备需要指定模型，请填写指定的模型ID，否则无需填写
A3: 名称* | B3: 制造厂家* | C3: 设备型号* | D3: 热管理机组类型* | E3: 热管理机组层级* | F3: 所属舱* | G3: 覆盖电池包数量* | H3: 覆盖电池簇数量* | I3: 所属电池组编号* | J3: 序号* | K3: Scada别名 | L3: 模型ID

Sheet 9-电表
A1: #填写说明# 1. 此模版为电表基础信息表，此页为必填页 2. 标注“*”的为重要填写项 3. 已标明单位的填写项直接按单位写入相应参数值，填写时不能带有单位
A2: 填写指导： | B2: 如有多种厂家，需分别填写 | C2: 如有多种规格，需分别填写 | D2: 填写：场站级、系统级、电池组级 | E2: 电表类型：若是升压站进线电表，则填接入进线表，若是升压站出线关口表，则填出线关口表，若是储能系统计量电表，则填储能电表 | F2: 仪表读数的倍增因子 | G2: 正接：默认 反接：如果有功能量反向用于产生的能量计算 | H2: 所属的储能系统 若属于场站层级电表，则无需填写 | I2: 仅EnOS需填写： 关口表斜率需要是场站额定功率2倍，单位kW 储能表斜率需要是所属系统额定功率的2倍，单位kW 其他类型电表不做要求 | J2: 仅EnOS需填写： 电量表在场站内的编号，要求不超过3位，如：“01”，表示在场站内的1号电表 | K2: 仅EnOS需填写： 站端scada的scada别名 | L2: 仅EnOS需填写：（远景填写） 如果创建设备需要指定模型，请填写指定的模型ID，否则无需填写
A3: 名称* | B3: 制造厂家* | C3: 设备型号* | D3: 电表所属层级* | E3: 类型* | F3: 倍率* | G3: 接入模式* | H3: 所属系统 | I3: 斜率* | J3: 序号* | K3: Scada别名 | L3: 模型ID

Sheet 11-其他设备
A1: #填写说明# 1. 此模版为“其他设备”基础信息表，此页为非必填页 2. 标注“*”的为重要填写项
A2: 填写指导： | B2: 设备类型 | C2: 如有多种厂家，需分别填写 | D2: 如有多种规格，需分别填写 | E2: 若属于场站层级，则无需填写； 若属于子系统级，则填写所属的储能系统； 若属于设备级，则填写所属的设备
A3: 名称* | B3: 设备类型* | C3: 制造厂家* | D3: 设备型号* | E3: 所属设备*

Sheet 常量定义
A1: 设备类型 | B1: 类型 | C1: 是否是间隔 | D1: 别名 | E1: 是否使用挂载别名（对于非间隔） | F1: 节点容器表是否需要
A2: 空调 | B2: Air Condition | C2: 1 | D2: AC | E2: 0 | F2: 1
A3: 电池组 | B3: BankBMS | C3: 1 | D3: BBMS | E3: 0 | F3: 1
A4: 储能单元电量表 | B4: Electric Meter | C4: 1 | D4: EMT | E4: 0 | F4: 1
A5: 配电电度表 | B5: Auxiliary Electricity Meter | C5: 1 | D5: EMT | E5: 0 | F5: 1
A6: 交流液冷控制器 | B6: Liquid Cooling Control | C6: 1 | D6: LCC | E6: 0 | F6: 1
A7: 变流器 | B7: Power Conversion System | C7: 1 | D7: PCS | E7: 0 | F7: 1
A8: 电池簇 | B8: RackBMS | C8: 1 | D8: RBMS | E8: 0 | F8: 1
A9: 动力单元 | B9: Battery | C9: 0 | D9: B | E9: 0 | F9: 0
A10: 舱 | B10: Cabin | C10: 0 | D10: C | E10: 0 | F10: 0
A11: 能量管理 | B11: Energy Management System | C11: 0 | D11: EMS | E11: 0 | F11: 0
A12: 测控装置 | B12: Measurement and Control Device | C12: 0 | D12: TMM | E12: 0 | F12: 0
A13: 系统设置 | B13: System | C13: 0 | D13: SYS | E13: 0 | F13: 0
... A40: 储能协调控制装置 | B40: Other,Other device,Other | C40: 1 | D40: Farm.CCD | E40: 0 | F40: 1

Sheet 10-消防|Fire Protection 
A1: #填写说明# 1. 此模版为消防基础信息表，此页为必填页 2. 标注“*”的为重要填写项 3. 已标明单位的填写项直接按单位写入相应参数值，填写时不能带有单位 | D1: #Notes# 1. This template is the basic information table of the fire protection, and this page is a required page. 2. Items marked with "*" are important items. 3. The input items that have marked the unit are directly written in the corresponding parameter values according to the unit, and the unit cannot be filled in.
A2: 填写指导： | B2: 填写：控制系统、抑制系统、探测系统。其中，控制系统对应显控主机和报警装置，抑制系统对应抑制主机，探测系统对应探测装置。 | C2: 如有多种厂家，需分别填写 | D2: 如有多种规格，需分别填写 | E2: 填写：电池组级、电池簇级、电池包级 | F2: 仅对于探测系统，填写是否包含包级探测器 | G2: 仅对于探测系统，若存在包级探测器，则填写数量 | H2: 所属的储能系统
A3: Instructions: | B3: Fill in: Control system, Suppression system, Detection system. The control system corresponds to the display control host and alarm device, the suppression system corresponds to the suppression host, and the detection system corresponds to the detection device. | C3: If there are multiple manufacturers, they need to be filled in separately. | D3: If there are multiple specifications, they need to be filled in separately. | E3: Fill in: Bank level, Rack level, Pack level | F3: For detection system only, fill in whether pack-level detections are included | G3: For detection system only, fill in the quantity whether pack-level detections are included | H3: The energy storage unit to which the device belongs.
A4: 名称* | B4: 消防设备类型* | C4: 制造厂家* | D4: 设备型号* | E4: 消防设备层级* | F4: 是否包含包级探测器* | G4: 包级探测器数量* | H4: 所属系统*
A5: Name* | B5: Device Type* | C5: Manufacturer* | D5: Model* | E5: Level* | F5: Rack Detector | G5: Pack Detector | H5: Corresponding unit*

Sheet 10-电芯数据
A1: 电芯数据采集方式：实时采集或记录文件采集，需提供记录文件采集格式

Sheet 11-全量枚举值定义(选填)
A1: 设备类型 | B1: 枚举值中文描述 | C1: 枚举值英文描述 | D1: 枚举值

Sheet 12-告警信息收集

Sheet 10-消防设备
A1: #填写说明# 1. 此模版为储能消防设备基础信息表，若场站无法采集消防设备也可不填 2. 标注“*”的为重要填写项 3. 已标明单位的填写项直接按单位写入相应参数值，填写时不能带有单位
A2: 填写指导： | B2: 如有多种厂家，需分别填写 | C2: 如有多种规格，需分别填写 | D2: 包含：探测系统、控制系统、抑制系统 其中，探测系统对应探测装置，控制系统对应显控主机和报警装置，抑制系统对应抑制主机 | E2: 填写：系统级、电池组级、电池簇级 | F2: 仅对于探测系统，填写是否包含包级探测器，yes或no | G2: 仅对于探测系统，电池组级别需要填写，yes或no | H2: 仅对于探测系统，若存在包级探测器，则填写数量，若不存在则不填 | I2: 消防设备所属的上级节点 | J2: 仅EnOS需填写： 站端scada的scada别名 | K2: 仅EnOS需填写：（远景填写） 如果创建设备需要指定模型，请填写指定的模型ID，否则无需填写
A3: 名称* | B3: 制造厂家* | C3: 设备型号* | D3: 消防设备类型* | E3: 消防设备层级* | F3: 是否包含包级探测器 | G3: 是否包含簇级探测器 | H3: 包级探测器数量 | I3: 所属上级设备* | J3: Scada别名 | K3: 模型ID
A4: 1舱1堆消防控制器 | B4: 威胜集团有限公司 | C4: DTZ22 | D4: 消防控制 | E4: 电池组级 | I4: 1-1电池管理系统
A5: 1舱2堆消防控制器 | B5: 威胜集团有限公司 | C5: DTZ22 | D5: 消防控制 | E5: 电池组级 | I5: 1-2电池管理系统
A6: 2舱1堆消防控制器 | B6: 威胜集团有限公司 | C6: DTZ22 | D6: 消防控制 | E6: 电池组级 | I6: 2-1电池管理系统
A7: 2舱2堆消防控制器 | B7: 威胜集团有限公司 | C7: DTZ22 | D7: 消防控制 | E7: 电池组级 | I7: 2-2电池管理系统
A8: 3舱1堆消防控制器 | B8: 威胜集团有限公司 | C8: DTZ22 | D8: 消防控制 | E8: 电池组级 | I8: 3-1电池管理系统
A9: 3舱2堆消防控制器 | B9: 威胜集团有限公司 | C9: DTZ22 | D9: 消防控制 | E9: 电池组级 | I9: 3-2电池管理系统
A10: 4舱1堆消防控制器 | B10: 威胜集团有限公司 | C10: DTZ22 | D10: 消防控制 | E10: 电池组级 | I10: 4-1电池管理系统
A11: 4舱2堆消防控制器 | B11: 威胜集团有限公司 | C11: DTZ22 | D11: 消防控制 | E11: 电池组级 | I11: 4-2电池管理系统
A12: 5舱1堆消防控制器 | B12: 威胜集团有限公司 | C12: DTZ22 | D12: 消防控制 | E12: 电池组级 | I12: 5-1电池管理系统
A13: 5舱2堆消防控制器 | B13: 威胜集团有限公司 | C13: DTZ22 | D13: 消防控制 | E13: 电池组级 | I13: 5-2电池管理系统
A14: 6舱1堆消防控制器 | B14: 威胜集团有限公司 | C14: DTZ22 | D14: 消防控制 | E14: 电池组级 | I14: 6-1电池管理系统
A15: 6舱2堆消防控制器 | B15: 威胜集团有限公司 | C15: DTZ22 | D15: 消防控制 | E15: 电池组级 | I15: 6-2电池管理系统
... A31: 7舱2堆消防抑制器 | B31: 威胜集团有限公司 | C31: DTZ22 | D31: 消防抑制 | E31: 电池组级 | I31: 7-2电池管理系统
A32: 1舱1堆电池簇1消防探测器 | B32: 威胜集团有限公司 | C32: DTZ22 | D32: 消防探测 | E32: 电池簇级 | F32: 0-no | H32: 8 | I32: 1舱1堆电池簇1
A33: 1舱1堆电池簇2消防探测器 | B33: 威胜集团有限公司 | C33: DTZ22 | D33: 消防探测 | E33: 电池簇级 | F33: 0-no | H33: 8 | I33: 1舱1堆电池簇2
A34: 1舱1堆电池簇3消防探测器 | B34: 威胜集团有限公司 | C34: DTZ22 | D34: 消防探测 | E34: 电池簇级 | F34: 0-no | H34: 8 | I34: 1舱1堆电池簇3
A35: 1舱1堆电池簇4消防探测器 | B35: 威胜集团有限公司 | C35: DTZ22 | D35: 消防探测 | E35: 电池簇级 | F35: 0-no | H35: 8 | I35: 1舱1堆电池簇4
A36: 1舱1堆电池簇5消防探测器 | B36: 威胜集团有限公司 | C36: DTZ22 | D36: 消防探测 | E36: 电池簇级 | F36: 0-no | H36: 8 | I36: 1舱1堆电池簇5
A37: 1舱2堆电池簇1消防探测器 | B37: 威胜集团有限公司 | C37: DTZ22 | D37: 消防探测 | E37: 电池簇级 | F37: 0-no | H37: 8 | I37: 1舱2堆电池簇1
A38: 1舱2堆电池簇2消防探测器 | B38: 威胜集团有限公司 | C38: DTZ22 | D38: 消防探测 | E38: 电池簇级 | F38: 0-no | H38: 8 | I38: 1舱2堆电池簇2
A39: 1舱2堆电池簇3消防探测器 | B39: 威胜集团有限公司 | C39: DTZ22 | D39: 消防探测 | E39: 电池簇级 | F39: 0-no | H39: 8 | I39: 1舱2堆电池簇3
A40: 1舱2堆电池簇4消防探测器 | B40: 威胜集团有限公司 | C40: DTZ22 | D40: 消防探测 | E40: 电池簇级 | F40: 0-no | H40: 8 | I40: 1舱2堆电池簇4
A41: 1舱2堆电池簇5消防探测器 | B41: 威胜集团有限公司 | C41: DTZ22 | D41: 消防探测 | E41: 电池簇级 | F41: 0-no | H41: 8 | I41: 1舱2堆电池簇5
A42: 2舱1堆电池簇1消防探测器 | B42: 威胜集团有限公司 | C42: DTZ22 | D42: 消防探测 | E42: 电池簇级 | F42: 0-no | H42: 8 | I42: 2舱1堆电池簇1
A43: 2舱1堆电池簇2消防探测器 | B43: 威胜集团有限公司 | C43: DTZ22 | D43: 消防探测 | E43: 电池簇级 | F43: 0-no | H43: 8 | I43: 2舱1堆电池簇2
... A101: 7舱2堆电池簇5消防探测器 | B101: 威胜集团有限公司 | C101: DTZ22 | D101: 消防探测 | E101: 电池簇级 | F101: 0-no | H101: 8 | I101: 7舱2堆电池簇5

Sheet Sheet1
A1: 电池组级 | B1: 电池簇级 | C1: 系统级
A2: =IF('6-电池组'!#REF!="","",'6-电池组'!#REF!) -> #REF! | B2: =IF('7-电池簇'!#REF!="","",'7-电池簇'!#REF!) -> #REF! | C2: =IF('2-储能系统'!#REF!="","",'2-储能系统'!#REF!) -> #REF!
A3: =IF('6-电池组'!#REF!="","",'6-电池组'!#REF!) -> #REF! | B3: =IF('7-电池簇'!#REF!="","",'7-电池簇'!#REF!) -> #REF! | C3: =IF('2-储能系统'!#REF!="","",'2-储能系统'!#REF!) -> #REF!
A4: =IF('6-电池组'!#REF!="","",'6-电池组'!#REF!) -> #REF! | B4: =IF('7-电池簇'!#REF!="","",'7-电池簇'!#REF!) -> #REF! | C4: =IF('2-储能系统'!#REF!="","",'2-储能系统'!#REF!) -> #REF!
A5: =IF('6-电池组'!#REF!="","",'6-电池组'!#REF!) -> #REF! | B5: =IF('7-电池簇'!#REF!="","",'7-电池簇'!#REF!) -> #REF! | C5: =IF('2-储能系统'!#REF!="","",'2-储能系统'!#REF!) -> #REF!
A6: =IF('6-电池组'!#REF!="","",'6-电池组'!#REF!) -> #REF! | B6: =IF('7-电池簇'!#REF!="","",'7-电池簇'!#REF!) -> #REF! | C6: =IF('2-储能系统'!#REF!="","",'2-储能系统'!#REF!) -> #REF!
A7: =IF('6-电池组'!#REF!="","",'6-电池组'!#REF!) -> #REF! | B7: =IF('7-电池簇'!#REF!="","",'7-电池簇'!#REF!) -> #REF! | C7: =IF('2-储能系统'!#REF!="","",'2-储能系统'!#REF!) -> #REF!
A8: =IF('6-电池组'!#REF!="","",'6-电池组'!#REF!) -> #REF! | B8: =IF('7-电池簇'!#REF!="","",'7-电池簇'!#REF!) -> #REF! | C8: =IF('2-储能系统'!#REF!="","",'2-储能系统'!#REF!) -> #REF!
A9: =IF('6-电池组'!#REF!="","",'6-电池组'!#REF!) -> #REF! | B9: =IF('7-电池簇'!#REF!="","",'7-电池簇'!#REF!) -> #REF! | C9: =IF('2-储能系统'!#REF!="","",'2-储能系统'!#REF!) -> #REF!
A10: =IF('6-电池组'!#REF!="","",'6-电池组'!#REF!) -> #REF! | B10: =IF('7-电池簇'!#REF!="","",'7-电池簇'!#REF!) -> #REF! | C10: =IF('2-储能系统'!#REF!="","",'2-储能系统'!#REF!) -> #REF!
A11: =IF('6-电池组'!#REF!="","",'6-电池组'!#REF!) -> #REF! | B11: =IF('7-电池簇'!#REF!="","",'7-电池簇'!#REF!) -> #REF! | C11: =IF('2-储能系统'!#REF!="","",'2-储能系统'!#REF!) -> #REF!
A12: =IF('6-电池组'!#REF!="","",'6-电池组'!#REF!) -> #REF! | B12: =IF('7-电池簇'!#REF!="","",'7-电池簇'!#REF!) -> #REF! | C12: =IF('2-储能系统'!#REF!="","",'2-储能系统'!#REF!) -> #REF!
A13: =IF('6-电池组'!#REF!="","",'6-电池组'!#REF!) -> #REF! | B13: =IF('7-电池簇'!#REF!="","",'7-电池簇'!#REF!) -> #REF! | C13: =IF('2-储能系统'!#REF!="","",'2-储能系统'!#REF!) -> #REF!
... A23: =IF('6-电池组'!#REF!="","",'6-电池组'!#REF!) -> #REF! | B23: =IF('7-电池簇'!#REF!="","",'7-电池簇'!#REF!) -> #REF! | C23: =IF('2-储能系统'!#REF!="","",'2-储能系统'!#REF!) -> #REF!
A24: =IF('6-电池组'!A4="","",'6-电池组'!A4) | B24: =IF('7-电池簇'!#REF!="","",'7-电池簇'!#REF!) -> #REF! | C24: =IF('2-储能系统'!#REF!="","",'2-储能系统'!#REF!) -> #REF!
A25: =IF('6-电池组'!A5="","",'6-电池组'!A5) | B25: =IF('7-电池簇'!#REF!="","",'7-电池簇'!#REF!) -> #REF! | C25: =IF('2-储能系统'!#REF!="","",'2-储能系统'!#REF!) -> #REF!
A26: =IF('6-电池组'!A6="","",'6-电池组'!A6) | B26: =IF('7-电池簇'!#REF!="","",'7-电池簇'!#REF!) -> #REF! | C26: =IF('2-储能系统'!#REF!="","",'2-储能系统'!#REF!) -> #REF!
A27: =IF('6-电池组'!A7="","",'6-电池组'!A7) | B27: =IF('7-电池簇'!#REF!="","",'7-电池簇'!#REF!) -> #REF! | C27: =IF('2-储能系统'!#REF!="","",'2-储能系统'!#REF!) -> #REF!
A28: =IF('6-电池组'!A8="","",'6-电池组'!A8) | B28: =IF('7-电池簇'!#REF!="","",'7-电池簇'!#REF!) -> #REF! | C28: =IF('2-储能系统'!#REF!="","",'2-储能系统'!#REF!) -> #REF!
A29: =IF('6-电池组'!A9="","",'6-电池组'!A9) | B29: =IF('7-电池簇'!#REF!="","",'7-电池簇'!#REF!) -> #REF! | C29: =IF('2-储能系统'!#REF!="","",'2-储能系统'!#REF!) -> #REF!
A30: =IF('6-电池组'!A10="","",'6-电池组'!A10) | B30: =IF('7-电池簇'!#REF!="","",'7-电池簇'!#REF!) -> #REF! | C30: =IF('2-储能系统'!#REF!="","",'2-储能系统'!#REF!) -> #REF!
A31: =IF('6-电池组'!A11="","",'6-电池组'!A11) | B31: =IF('7-电池簇'!#REF!="","",'7-电池簇'!#REF!) -> #REF! | C31: =IF('2-储能系统'!#REF!="","",'2-储能系统'!#REF!) -> #REF!
A32: =IF('6-电池组'!A12="","",'6-电池组'!A12) | B32: =IF('7-电池簇'!#REF!="","",'7-电池簇'!#REF!) -> #REF! | C32: =IF('2-储能系统'!#REF!="","",'2-储能系统'!#REF!) -> #REF!
A33: =IF('6-电池组'!A13="","",'6-电池组'!A13) | B33: =IF('7-电池簇'!#REF!="","",'7-电池簇'!#REF!) -> #REF! | C33: =IF('2-储能系统'!#REF!="","",'2-储能系统'!#REF!) -> #REF!
A34: =IF('6-电池组'!A14="","",'6-电池组'!A14) | B34: =IF('7-电池簇'!#REF!="","",'7-电池簇'!#REF!) -> #REF! | C34: =IF('2-储能系统'!#REF!="","",'2-储能系统'!#REF!) -> #REF!
A35: =IF('6-电池组'!A15="","",'6-电池组'!A15) | B35: =IF('7-电池簇'!#REF!="","",'7-电池簇'!#REF!) -> #REF! | C35: =IF('2-储能系统'!#REF!="","",'2-储能系统'!#REF!) -> #REF!
... A72: =IF('6-电池组'!A52="","",'6-电池组'!A52) | B72: =IF('7-电池簇'!#REF!="","",'7-电池簇'!#REF!) -> #REF! | C72: =IF('2-储能系统'!#REF!="","",'2-储能系统'!#REF!) -> #REF!
A73: =IF('6-电池组'!A53="","",'6-电池组'!A53) | B73: =IF('7-电池簇'!A4="","",'7-电池簇'!A4) | C73: =IF('2-储能系统'!#REF!="","",'2-储能系统'!#REF!) -> #REF!
A74: =IF('6-电池组'!A54="","",'6-电池组'!A54) | B74: =IF('7-电池簇'!A5="","",'7-电池簇'!A5) | C74: =IF('2-储能系统'!#REF!="","",'2-储能系统'!#REF!) -> #REF!
A75: =IF('6-电池组'!A55="","",'6-电池组'!A55) | B75: =IF('7-电池簇'!A6="","",'7-电池簇'!A6) | C75: =IF('2-储能系统'!#REF!="","",'2-储能系统'!#REF!) -> #REF!
A76: =IF('6-电池组'!A56="","",'6-电池组'!A56) | B76: =IF('7-电池簇'!A7="","",'7-电池簇'!A7) | C76: =IF('2-储能系统'!#REF!="","",'2-储能系统'!#REF!) -> #REF!
A77: =IF('6-电池组'!A57="","",'6-电池组'!A57) | B77: =IF('7-电池簇'!A8="","",'7-电池簇'!A8) | C77: =IF('2-储能系统'!#REF!="","",'2-储能系统'!#REF!) -> #REF!
A78: =IF('6-电池组'!A58="","",'6-电池组'!A58) | B78: =IF('7-电池簇'!A9="","",'7-电池簇'!A9) | C78: =IF('2-储能系统'!#REF!="","",'2-储能系统'!#REF!) -> #REF!
A79: =IF('6-电池组'!A59="","",'6-电池组'!A59) | B79: =IF('7-电池簇'!A10="","",'7-电池簇'!A10) | C79: =IF('2-储能系统'!#REF!="","",'2-储能系统'!#REF!) -> #REF!
A80: =IF('6-电池组'!A60="","",'6-电池组'!A60) | B80: =IF('7-电池簇'!A11="","",'7-电池簇'!A11) | C80: =IF('2-储能系统'!#REF!="","",'2-储能系统'!#REF!) -> #REF!
A81: =IF('6-电池组'!A61="","",'6-电池组'!A61) | B81: =IF('7-电池簇'!A12="","",'7-电池簇'!A12) | C81: =IF('2-储能系统'!#REF!="","",'2-储能系统'!#REF!) -> #REF!
A82: =IF('6-电池组'!A62="","",'6-电池组'!A62) | B82: =IF('7-电池簇'!A13="","",'7-电池簇'!A13) | C82: =IF('2-储能系统'!#REF!="","",'2-储能系统'!#REF!) -> #REF!
A83: =IF('6-电池组'!A63="","",'6-电池组'!A63) | B83: =IF('7-电池簇'!A14="","",'7-电池簇'!A14) | C83: =IF('2-储能系统'!#REF!="","",'2-储能系统'!#REF!) -> #REF!
A84: =IF('6-电池组'!A64="","",'6-电池组'!A64) | B84: =IF('7-电池簇'!A15="","",'7-电池簇'!A15) | C84: =IF('2-储能系统'!#REF!="","",'2-储能系统'!#REF!) -> #REF!
... A321: =IF('6-电池组'!A301="","",'6-电池组'!A301) | B321: =IF('7-电池簇'!A252="","",'7-电池簇'!A252) | C321: =IF('2-储能系统'!#REF!="","",'2-储能系统'!#REF!) -> #REF!
...
